void main()
{

  // assert function throws exception when first argument evalutes to false
 try {
   assert(1>2,"1 is greater than 2");
 }
  catch(e)
{
  print(e);
}
  print("hello");

}